[2023-05-25 22:23:31,433] {taskinstance.py:1159} INFO - Dependencies all met for <TaskInstance: Dados_clima.Extrair_dados scheduled__2023-05-01T00:00:00+00:00 [queued]>
[2023-05-25 22:23:31,443] {taskinstance.py:1159} INFO - Dependencies all met for <TaskInstance: Dados_clima.Extrair_dados scheduled__2023-05-01T00:00:00+00:00 [queued]>
[2023-05-25 22:23:31,443] {taskinstance.py:1356} INFO - 
--------------------------------------------------------------------------------
[2023-05-25 22:23:31,443] {taskinstance.py:1357} INFO - Starting attempt 1 of 1
[2023-05-25 22:23:31,443] {taskinstance.py:1358} INFO - 
--------------------------------------------------------------------------------
[2023-05-25 22:23:31,458] {taskinstance.py:1377} INFO - Executing <Task(PythonOperator): Extrair_dados> on 2023-05-01 00:00:00+00:00
[2023-05-25 22:23:31,462] {standard_task_runner.py:52} INFO - Started process 110771 to run task
[2023-05-25 22:23:31,465] {standard_task_runner.py:79} INFO - Running: ['airflow', 'tasks', 'run', 'Dados_clima', 'Extrair_dados', 'scheduled__2023-05-01T00:00:00+00:00', '--job-id', '53', '--raw', '--subdir', 'DAGS_FOLDER/Climas.py', '--cfg-path', '/tmp/tmp_r94g_yu', '--error-file', '/tmp/tmpgz74b9lq']
[2023-05-25 22:23:31,466] {standard_task_runner.py:80} INFO - Job 53: Subtask Extrair_dados
[2023-05-25 22:23:31,531] {task_command.py:370} INFO - Running <TaskInstance: Dados_clima.Extrair_dados scheduled__2023-05-01T00:00:00+00:00 [running]> on host enricolm-virtual-machine
[2023-05-25 22:23:31,597] {taskinstance.py:1569} INFO - Exporting the following env vars:
AIRFLOW_CTX_DAG_OWNER=airflow
AIRFLOW_CTX_DAG_ID=Dados_clima
AIRFLOW_CTX_TASK_ID=Extrair_dados
AIRFLOW_CTX_EXECUTION_DATE=2023-05-01T00:00:00+00:00
AIRFLOW_CTX_TRY_NUMBER=1
AIRFLOW_CTX_DAG_RUN_ID=scheduled__2023-05-01T00:00:00+00:00
[2023-05-25 22:23:31,598] {taskinstance.py:1889} ERROR - Task failed with exception
Traceback (most recent call last):
  File "/home/enricolm/Documents/airflowalura/venv/lib/python3.9/site-packages/airflow/operators/python.py", line 171, in execute
    return_value = self.execute_callable()
  File "/home/enricolm/Documents/airflowalura/venv/lib/python3.9/site-packages/airflow/operators/python.py", line 189, in execute_callable
    return self.python_callable(*self.op_args, **self.op_kwargs)
  File "/home/enricolm/Documents/airflowalura/dags/Climas.py", line 16, in extraindo_dados
    os.chdir('~/Desktop/AirFlow')
FileNotFoundError: [Errno 2] No such file or directory: '~/Desktop/AirFlow'
[2023-05-25 22:23:31,603] {taskinstance.py:1395} INFO - Marking task as FAILED. dag_id=Dados_clima, task_id=Extrair_dados, execution_date=20230501T000000, start_date=20230526T012331, end_date=20230526T012331
[2023-05-25 22:23:31,614] {standard_task_runner.py:92} ERROR - Failed to execute job 53 for task Extrair_dados ([Errno 2] No such file or directory: '~/Desktop/AirFlow'; 110771)
[2023-05-25 22:23:31,648] {local_task_job.py:156} INFO - Task exited with return code 1
[2023-05-25 22:23:31,668] {local_task_job.py:273} INFO - 0 downstream tasks scheduled from follow-on schedule check
[2023-05-25 22:23:31,677] {dagrun.py:547} ERROR - Marking run <DagRun Dados_clima @ 2023-05-01 00:00:00+00:00: scheduled__2023-05-01T00:00:00+00:00, externally triggered: False> failed
[2023-05-25 22:23:31,677] {dagrun.py:607} INFO - DagRun Finished: dag_id=Dados_clima, execution_date=2023-05-01 00:00:00+00:00, run_id=scheduled__2023-05-01T00:00:00+00:00, run_start_date=2023-05-26 01:23:29.941347+00:00, run_end_date=2023-05-26 01:23:31.677227+00:00, run_duration=1.73588, state=failed, external_trigger=False, run_type=scheduled, data_interval_start=2023-05-01 00:00:00+00:00, data_interval_end=2023-05-08 00:00:00+00:00, dag_hash=2fde0247ca60c8a1f7d62f4c346e80ef
