[2023-05-25 22:23:29,182] {taskinstance.py:1159} INFO - Dependencies all met for <TaskInstance: Dados_clima.Extrair_dados scheduled__2023-04-24T00:00:00+00:00 [queued]>
[2023-05-25 22:23:29,190] {taskinstance.py:1159} INFO - Dependencies all met for <TaskInstance: Dados_clima.Extrair_dados scheduled__2023-04-24T00:00:00+00:00 [queued]>
[2023-05-25 22:23:29,190] {taskinstance.py:1356} INFO - 
--------------------------------------------------------------------------------
[2023-05-25 22:23:29,191] {taskinstance.py:1357} INFO - Starting attempt 1 of 1
[2023-05-25 22:23:29,191] {taskinstance.py:1358} INFO - 
--------------------------------------------------------------------------------
[2023-05-25 22:23:29,205] {taskinstance.py:1377} INFO - Executing <Task(PythonOperator): Extrair_dados> on 2023-04-24 00:00:00+00:00
[2023-05-25 22:23:29,210] {standard_task_runner.py:52} INFO - Started process 110757 to run task
[2023-05-25 22:23:29,216] {standard_task_runner.py:79} INFO - Running: ['airflow', 'tasks', 'run', 'Dados_clima', 'Extrair_dados', 'scheduled__2023-04-24T00:00:00+00:00', '--job-id', '52', '--raw', '--subdir', 'DAGS_FOLDER/Climas.py', '--cfg-path', '/tmp/tmpd_gehite', '--error-file', '/tmp/tmpjjos7e8s']
[2023-05-25 22:23:29,217] {standard_task_runner.py:80} INFO - Job 52: Subtask Extrair_dados
[2023-05-25 22:23:29,280] {task_command.py:370} INFO - Running <TaskInstance: Dados_clima.Extrair_dados scheduled__2023-04-24T00:00:00+00:00 [running]> on host enricolm-virtual-machine
[2023-05-25 22:23:29,323] {taskinstance.py:1569} INFO - Exporting the following env vars:
AIRFLOW_CTX_DAG_OWNER=airflow
AIRFLOW_CTX_DAG_ID=Dados_clima
AIRFLOW_CTX_TASK_ID=Extrair_dados
AIRFLOW_CTX_EXECUTION_DATE=2023-04-24T00:00:00+00:00
AIRFLOW_CTX_TRY_NUMBER=1
AIRFLOW_CTX_DAG_RUN_ID=scheduled__2023-04-24T00:00:00+00:00
[2023-05-25 22:23:29,325] {taskinstance.py:1889} ERROR - Task failed with exception
Traceback (most recent call last):
  File "/home/enricolm/Documents/airflowalura/venv/lib/python3.9/site-packages/airflow/operators/python.py", line 171, in execute
    return_value = self.execute_callable()
  File "/home/enricolm/Documents/airflowalura/venv/lib/python3.9/site-packages/airflow/operators/python.py", line 189, in execute_callable
    return self.python_callable(*self.op_args, **self.op_kwargs)
  File "/home/enricolm/Documents/airflowalura/dags/Climas.py", line 16, in extraindo_dados
    os.chdir('~/Desktop/AirFlow')
FileNotFoundError: [Errno 2] No such file or directory: '~/Desktop/AirFlow'
[2023-05-25 22:23:29,328] {taskinstance.py:1395} INFO - Marking task as FAILED. dag_id=Dados_clima, task_id=Extrair_dados, execution_date=20230424T000000, start_date=20230526T012329, end_date=20230526T012329
[2023-05-25 22:23:29,337] {standard_task_runner.py:92} ERROR - Failed to execute job 52 for task Extrair_dados ([Errno 2] No such file or directory: '~/Desktop/AirFlow'; 110757)
[2023-05-25 22:23:29,351] {local_task_job.py:156} INFO - Task exited with return code 1
[2023-05-25 22:23:29,369] {local_task_job.py:273} INFO - 0 downstream tasks scheduled from follow-on schedule check
